<?xml version="1.0"?>

<!-- Add a basic shape to get the robot working -->
<robot xmlns:xacro="http://www.ros.org/wiki/xacro">

    <xacro:macro name="robot" params="name parent pos_x pos_y">
        <link name="${name}">
            <visual>
                <origin xyz="${pos_x} ${pos_y} 0" rpy="0.0 0.0 0.0"/>
                <geometry>
                    <box size="0.4 0.4 0.1"/>
                </geometry>
                <!-- <material name="blue"/> -->
            </visual>
        </link>

        <joint name="${parent}_to_${name}_joint" type="planar">
            <origin xyz="0 0 0" rpy="0 0 0"/>
            
            <parent link="${parent}"/>
            <child link="${name}"/>

            <axis xyz="0 0 1"/>
            
        </joint>
    </xacro:macro>

</robot>